Workbook

Sheet DATA
A1: Proyecto | B1: Asesor | C1: N° | D1: Días Hábiles | E1: Periodo | F1: Desde | G1: Hasta | H1: Adelanto $ | I1: Negocios | J1: Departamentos a visitar | K1: Auto | L1: Costo Vehículo USD | M1: diferencia a pagar | N1: Boletas presentadas | O1: Negocios a Menos 100 KM (con o sin actividad) | P1: Negocios a Más de 100 KM (con o sin actividad) | Q1: Total Negocios | R1: Costo por negocio | S1: Cuenta Corriente | T1: Fecha Rendicion | U1: Tiempo | V1: Forma | W1: Detalle CI | X1: Observaciones de T y F | Y1: Matricula | Z1: Control de entrega a adm. | AA1: Factura | AB1: Fecha de Pago | AC1: Monto Factura | AD1: incial Km | AE1: incial fecha y hora | AF1: final Km | AG1: final fecha y hora | AH1: Km totales | AI1: Dias | AJ1: Negocios esperados | AK1: Diferencia | AM1: km * Afiliacion ida y vuelta | AN1: Afiliaciones * día | AO1: Criterio 11 km p/litro Max $ teorico | AP1: A favor + o negativo gasto mas de lo teorico | AQ1: Litros rendidos | AR1: Litros teoricos | AS1: Litros teoricos menos reales | AT1: Rendimiento real | AU1: Salida Gabriela con Asesor 1 | AV1: Salida Gabriela con Asesor 2 | AW1: Salida Gabriela con Asesor 3 | AX1: Salida Gabriela con Asesor 4 | AY1: Proyecto de Gabriela?
A2: 1 | B2: Ignacio Ceroni | C2: 3007 | D2: 4 | E2: 05/01 al 08/01/2026 | F2: 46027 | G2: 46030 | H2: 5000 | I2: 15 | J2: Montevideo, Maldonado | K2: Alquiler | M2: =+N2-H2 -> 58.9 | N2: =2458.9+2000+600 -> 5058.9 | P2: =20+6 -> 26 | Q2: =+P2+O2 -> 26 | R2: =(N2/Q2) -> 194.57308 | S2: =(('Costo por negocio'!$B$2-DATA!R2)*DATA!O2)+('Costo por negocio'!$C$2-DATA!R2)*DATA!P2 -> 5133.1 | T2: 46031 | U2: SI | V2: SI | W2: SI | Y2: BEC 5478 | AA2: 94621 | AC2: 148 | AD2: 72534 | AE2: 46027.375 | AF2: 73864 | AG2: 46031.389 | AH2: =+AF2-AD2 -> 1330 | AI2: 3 | AJ2: =+AI2*5 -> 15 | AK2: =+Q2-AJ2 -> 11 | AM2: =+AH2/Q2 -> 51.153846 | AN2: =+Q2/AI2 -> 8.6666667 | AQ2: =+N2/78.54 -> 64.411765 | AR2: =+AH2/11 -> 120.90909 | AS2: =+AR2-AQ2 -> 56.497326 | AT2: =+AH2/AQ2 -> 20.648402
A3: 2 | B3: Claudia Parrilla | C3: 2005 | D3: 3 | E3: 07/01 al 09/01/2026 | F3: 46029 | G3: 46031 | H3: 5000 | I3: 15 | J3: Montevideo, San José | K3: Alquiler | M3: =+N3-H3 -> -930.3 | N3: 4069.7 | O3: 7 | P3: 9 | Q3: =+P3+O3 -> 16 | R3: =(N3/Q3) -> 254.35625 | S3: =(('Costo por negocio'!$B$2-DATA!R3)*DATA!O3)+('Costo por negocio'!$C$2-DATA!R3)*DATA!P3 -> 1299.3 | T3: 46034 | U3: SI | V3: SI | W3: SI | Y3: BEB 1766 | AA3: 94630 | AC3: 111 | AD3: 121499 | AE3: 46029.398 | AF3: 122071 | AG3: 46032.376 | AH3: =+AF3-AD3 -> 572 | AI3: 3 | AJ3: =+AI3*5 -> 15 | AK3: =+Q3-AJ3 -> 1 | AM3: =+AH3/Q3 -> 35.75 | AN3: =+Q3/AI3 -> 5.3333333 | AQ3: =+N3/78.54 -> 51.816909 | AR3: =+AH3/11 -> 52 | AS3: =+AR3-AQ3 -> 0.18309142 | AT3: =+AH3/AQ3 -> 11.038868
A4: 3 | B4: Natalia Greco | C4: 3154 | D4: 3 | E4: 07/01 al 09/01/2026 | F4: 46029 | G4: 46031 | H4: 5000 | I4: 15 | J4: Montevideo, Lavalleja | K4: Alquiler | M4: =+N4-H4 -> -2333 | N4: =1500+1167 -> 2667 | P4: =8+7 -> 15 | Q4: =+P4+O4 -> 15 | R4: =(N4/Q4) -> 177.8 | S4: =(('Costo por negocio'!$B$2-DATA!R4)*DATA!O4)+('Costo por negocio'!$C$2-DATA!R4)*DATA!P4 -> 3213 | T4: 46034 | U4: SI | V4: SI | W4: SI | Y4: BEC 5664 | AA4: 94624 | AC4: 111 | AD4: 68806 | AE4: 46029.375 | AF4: 69300 | AG4: 46031.506 | AH4: =+AF4-AD4 -> 494 | AI4: 2 | AJ4: =+AI4*5 -> 10 | AK4: =+Q4-AJ4 -> 5 | AM4: =+AH4/Q4 -> 32.933333 | AN4: =+Q4/AI4 -> 7.5 | AQ4: =+N4/78.54 -> 33.957219 | AR4: =+AH4/11 -> 44.909091 | AS4: =+AR4-AQ4 -> 10.951872 | AT4: =+AH4/AQ4 -> 14.547717
A5: 4 | B5: Lorena Cabrera | C5: 1618 | D5: 3 | E5: 07/01 al 09/01/2026 | F5: 46029 | G5: 46031 | H5: 4000 | I5: 15 | J5: Canelones, Maldonado | K5: Alquiler | M5: =+N5-H5 -> -2125.5 | N5: 1874.5 | O5: 5 | Q5: =+P5+O5 -> 5 | R5: =(N5/Q5) -> 374.9 | S5: =(('Costo por negocio'!$B$2-DATA!R5)*DATA!O5)+('Costo por negocio'!$C$2-DATA!R5)*DATA!P5 -> -559.5 | T5: 46038 | U5: SI | V5: SI | W5: SI | Y5: BEB 2357 | AA5: 93044 | AC5: 111 | AD5: 134524 | AE5: 46029.375 | AF5: 134856 | AG5: 46032.375 | AH5: =+AF5-AD5 -> 332 | AI5: 3 | AJ5: =+AI5*5 -> 15 | AK5: =+Q5-AJ5 -> -10 | AM5: =+AH5/Q5 -> 66.4 | AN5: =+Q5/AI5 -> 1.6666667 | AQ5: =+N5/78.54 -> 23.866819 | AR5: =+AH5/11 -> 30.181818 | AS5: =+AR5-AQ5 -> 6.3149987 | AT5: =+AH5/AQ5 -> 13.910525
A6: 5 | B6: Ricardo Cardona | C6: 1512 | D6: 2 | E6: 07/01 al 08/01/2026 | F6: 46029 | G6: 46030 | H6: 6000 | I6: 10 | J6: Flores, Durazno | K6: Alquiler | M6: =+N6-H6 -> -2101.5 | N6: =2098+1000.5+800 -> 3898.5 | P6: 8 | Q6: =+P6+O6 -> 8 | R6: =(N6/Q6) -> 487.3125 | S6: =(('Costo por negocio'!$B$2-DATA!R6)*DATA!O6)+('Costo por negocio'!$C$2-DATA!R6)*DATA!P6 -> -762.5 | T6: 46031 | U6: SI | V6: SI | W6: SI | Y6: BEC 5528 | AA6: 94619 | AC6: 74 | AD6: 80882 | AE6: 46029.399 | AF6: 81499 | AG6: 46031.377 | AH6: =+AF6-AD6 -> 617 | AI6: 2 | AJ6: =+AI6*5 -> 10 | AK6: =+Q6-AJ6 -> -2 | AM6: =+AH6/Q6 -> 77.125 | AN6: =+Q6/AI6 -> 4 | AQ6: =+N6/78.54 -> 49.637128 | AR6: =+AH6/11 -> 56.090909 | AS6: =+AR6-AQ6 -> 6.4537815 | AT6: =+AH6/AQ6 -> 12.430212
A7: 6 | B7: Luis Amicone | C7: 3075 | D7: 3 | E7: 07/01 al 09/01/2026 | F7: 46029 | G7: 46031 | H7: 7000 | I7: 15 | J7: Montevideo, Treinta y Tres | K7: Alquiler | M7: =+N7-H7 -> -1984.9 | N7: =3020.1+1995 -> 5015.1 | P7: 20 | Q7: =+P7+O7 -> 20 | R7: =(N7/Q7) -> 250.755 | S7: =(('Costo por negocio'!$B$2-DATA!R7)*DATA!O7)+('Costo por negocio'!$C$2-DATA!R7)*DATA!P7 -> 2824.9 | T7: 46031 | U7: SI | V7: SI | W7: SI | Y7: BAA 7043 | AA7: 94618 | AC7: 74 | AD7: 108671 | AE7: 46029.42 | AF7: 109436 | AG7: 46031.378 | AH7: =+AF7-AD7 -> 765 | AI7: 2 | AJ7: =+AI7*5 -> 10 | AK7: =+Q7-AJ7 -> 10 | AM7: =+AH7/Q7 -> 38.25 | AN7: =+Q7/AI7 -> 10 | AQ7: =+N7/78.54 -> 63.854087 | AR7: =+AH7/11 -> 69.545455 | AS7: =+AR7-AQ7 -> 5.6913675 | AT7: =+AH7/AQ7 -> 11.980439
A8: 7 | B8: Ricardo Cardona | C8: 1512 | D8: 3 | E8: 13/01 al 15/01/2026 | F8: 46035 | G8: 46037 | H8: 7000 | I8: 15 | J8: Canelones, Maldonado | K8: Alquiler | M8: =+N8-H8 -> -2020.1 | N8: =2158.9+1406.8+1414.2 -> 4979.9 | P8: =3+3 -> 6 | Q8: =+P8+O8 -> 6 | R8: =(N8/Q8) -> 829.98333 | S8: =(('Costo por negocio'!$B$2-DATA!R8)*DATA!O8)+('Costo por negocio'!$C$2-DATA!R8)*DATA!P8 -> -2627.9 | T8: 46038 | U8: SI | V8: SI | W8: SI | Y8: BGC 5535 | AA8: 94661 | AC8: 148 | AD8: 65254 | AE8: 46034.684 | AF8: 66076 | AG8: 46038.384 | AH8: =+AF8-AD8 -> 822 | AI8: 3 | AJ8: =+AI8*5 -> 15 | AK8: =+Q8-AJ8 -> -9 | AM8: =+AH8/Q8 -> 137 | AN8: =+Q8/AI8 -> 2 | AQ8: =+N8/78.54 -> 63.405908 | AR8: =+AH8/11 -> 74.727273 | AS8: =+AR8-AQ8 -> 11.321365 | AT8: =+AH8/AQ8 -> 12.964092
A9: 8 | B9: Ignacio Ceroni | C9: 3007 | D9: 4 | E9: 12/01 al 15/01/2026 | F9: 46034 | G9: 46037 | H9: 4000 | I9: =5*4 -> 20 | J9: Montevideo, Maldonado | K9: Alquiler | M9: =+N9-H9 -> 405 | N9: =3005+1400 -> 4405 | O9: =11+10 -> 21 | P9: 9 | Q9: =+P9+O9 -> 30 | R9: =(N9/Q9) -> 146.83333 | S9: =(('Costo por negocio'!$B$2-DATA!R9)*DATA!O9)+('Costo por negocio'!$C$2-DATA!R9)*DATA!P9 -> 4646 | T9: 46038 | U9: SI | V9: SI | W9: SI | Y9: BEC 5472 | AA9: 94662 | AC9: 148 | AD9: 81576 | AE9: 46034.375 | AF9: 82324 | AG9: 46038.375 | AH9: =+AF9-AD9 -> 748 | AI9: 4 | AJ9: =+AI9*5 -> 20 | AK9: =+Q9-AJ9 -> 10 | AM9: =+AH9/Q9 -> 24.933333 | AN9: =+Q9/AI9 -> 7.5 | AQ9: =+N9/78.54 -> 56.086071 | AR9: =+AH9/11 -> 68 | AS9: =+AR9-AQ9 -> 11.913929 | AT9: =+AH9/AQ9 -> 13.336645
A10: 9 | B10: Claudia Parrilla | C10: 2005 | D10: 3 | E10: 13/01 al 15/01/2026 | F10: 46035 | G10: 46037 | H10: =18*263 -> 4734 | I10: 15 | J10: Montevideo, Canelones | K10: Alquiler | M10: =+N10-H10 -> -915.1 | N10: =2318.9+1500 -> 3818.9 | O10: 10 | P10: 7 | Q10: =+P10+O10 -> 17 | R10: =(N10/Q10) -> 224.64118 | S10: =(('Costo por negocio'!$B$2-DATA!R10)*DATA!O10)+('Costo por negocio'!$C$2-DATA!R10)*DATA!P10 -> 1555.1 | T10: 46038 | U10: SI | V10: SI | W10: SI | Y10: BEC 5634 | AA10: 94659 | AC10: 111 | AD10: 78912 | AE10: 46035.382 | AF10: 79558 | AG10: 46038.376 | AH10: =+AF10-AD10 -> 646 | AI10: 3 | AJ10: =+AI10*5 -> 15 | AK10: =+Q10-AJ10 -> 2 | AM10: =+AH10/Q10 -> 38 | AN10: =+Q10/AI10 -> 5.6666667 | AQ10: =+N10/78.54 -> 48.623631 | AR10: =+AH10/11 -> 58.727273 | AS10: =+AR10-AQ10 -> 10.103641 | AT10: =+AH10/AQ10 -> 13.285721
A11: 10 | B11: Luis Amicone | C11: 3075 | D11: 3 | E11: 13/01 al 15/01/2026 | F11: 46035 | G11: 46037 | H11: 8000 | I11: 15 | J11: Montevideo, Salto | K11: Alquiler | M11: =+N11-H11 -> 229.55 | N11: =2200.7+2479.5+2745+804.35 -> 8229.55 | P11: =20+5 -> 25 | Q11: =+P11+O11 -> 25 | R11: =(N11/Q11) -> 329.182 | S11: =(('Costo por negocio'!$B$2-DATA!R11)*DATA!O11)+('Costo por negocio'!$C$2-DATA!R11)*DATA!P11 -> 1570.45 | T11: 46038 | U11: SI | V11: SI | W11: SI | Y11: BED 8545 | AA11: 94660 | AC11: 148 | AD11: 21718 | AE11: 46034.681 | AF11: 23015 | AG11: 46038.381 | AH11: =+AF11-AD11 -> 1297 | AI11: 3 | AJ11: =+AI11*5 -> 15 | AK11: =+Q11-AJ11 -> 10 | AM11: =+AH11/Q11 -> 51.88 | AN11: =+Q11/AI11 -> 8.3333333 | AQ11: =+N11/78.54 -> 104.78164 | AR11: =+AH11/11 -> 117.90909 | AS11: =+AR11-AQ11 -> 13.127451 | AT11: =+AH11/AQ11 -> 12.378123
A12: 11 | B12: Ignacio Ceroni | C12: 3007 | D12: 8 | E12: 01/01 al 14/01/2026 | F12: 46023 | G12: 46036 | J12: Montevideo | K12: Propio | M12: =+N12-H12 -> 3100 | N12: 3100 | O12: 16 | Q12: =+P12+O12 -> 16 | R12: =(N12/Q12) -> 193.75 | S12: =(('Costo por negocio'!$B$2-DATA!R12)*DATA!O12)+('Costo por negocio'!$C$2-DATA!R12)*DATA!P12 -> 1108 | T12: 46031 | U12: SI | V12: SI | W12: SI | Y12: SCG 4199 | AH12: =+AF12-AD12 -> 0 | AJ12: =+AI12*5 -> 0 | AK12: 0
A13: 12 | B13: Luis Amicone | C13: 3075 | D13: 8 | E13: 01/01 al 14/01/2026 | F13: 46023 | G13: 46036 | J13: Montevideo | K13: Propio | M13: =+N13-H13 -> 1500 | N13: 1500 | O13: 3 | Q13: =+P13+O13 -> 3 | R13: =(N13/Q13) -> 500 | S13: =(('Costo por negocio'!$B$2-DATA!R13)*DATA!O13)+('Costo por negocio'!$C$2-DATA!R13)*DATA!P13 -> -711 | T13: 46031 | U13: SI | V13: SI | W13: SI | Y13: SDD 5511 | AH13: =+AF13-AD13 -> 0 | AJ13: =+AI13*5 -> 0 | AK13: 0
A14: 13 | B14: Leonardo de Tomas | C14: 3076 | D14: 6 | E14: 01/01 al 12/01/2026 | F14: 46023 | G14: 46034 | J14: Montevideo, Colonia, Maldonado | K14: Propio | M14: =+N14-H14 -> 11729.1 | N14: =2831+2637.1+2900+3361 -> 11729.1 | P14: =18+12 -> 30 | Q14: =+P14+O14 -> 30 | R14: =(N14/Q14) -> 390.97 | S14: =(('Costo por negocio'!$B$2-DATA!R14)*DATA!O14)+('Costo por negocio'!$C$2-DATA!R14)*DATA!P14 -> 30.9 | T14: 46034 | U14: SI | V14: SI | W14: SI | Y14: SCN 5181 | AH14: =+AF14-AD14 -> 0 | AJ14: =+AI14*5 -> 0 | AK14: 0
A15: 14 | B15: Rolando Ball | C15: 1332 | D15: 8 | E15: 01/01 al 14/01/2026 | F15: 46023 | G15: 46036 | J15: Rocha | K15: Propio | M15: =+N15-H15 -> 7000 | N15: =1000+1800+2400+1800 -> 7000 | O15: 21 | P15: 4 | Q15: =+P15+O15 -> 25 | R15: =(N15/Q15) -> 280 | S15: =(('Costo por negocio'!$B$2-DATA!R15)*DATA!O15)+('Costo por negocio'!$C$2-DATA!R15)*DATA!P15 -> 91 | T15: 46037 | U15: SI | V15: SI | W15: SI | Y15: CBD 1303
A16: 15 | B16: Agustin Buñevaz | C16: 3152 | D16: 8 | E16: 01/01 al 14/01/2026 | F16: 46023 | G16: 46036 | J16: Montevideo, Canelones | K16: Propio | M16: =+N16-H16 -> 6312 | N16: =792+1056+1052+1052+2360 -> 6312 | O16: 23 | Q16: =+P16+O16 -> 23 | R16: =(N16/Q16) -> 274.43478 | S16: =(('Costo por negocio'!$B$2-DATA!R16)*DATA!O16)+('Costo por negocio'!$C$2-DATA!R16)*DATA!P16 -> -263 | T16: 46037 | U16: SI | V16: SI | W16: SI | Y16: ABK 2846
A17: 16 | B17: Lucia Santamaría | C17: 3065 | D17: 8 | E17: 01/01 al 14/01/2026 | F17: 46023 | G17: 46036 | J17: Maldonado | K17: Propio | M17: =+N17-H17 -> 6675.4 | N17: =2553+1322.4+2800 -> 6675.4 | O17: =20+6 -> 26 | Q17: =+P17+O17 -> 26 | R17: =(N17/Q17) -> 256.74615 | S17: =(('Costo por negocio'!$B$2-DATA!R17)*DATA!O17)+('Costo por negocio'!$C$2-DATA!R17)*DATA!P17 -> 162.6 | T17: 46037 | U17: SI | V17: SI | W17: SI | Y17: SBI 6680
A18: 17 | B18: Claudia Parrilla | C18: 2005 | D18: 3 | E18: 20/01 al 22/01/2026 | F18: 46042 | G18: 46044 | H18: =18*392 -> 7056 | I18: 15 | J18: Montevideo, Colonia | K18: Alquiler | M18: =+N18-H18 -> -4240 | N18: 2816 | O18: 4 | P18: 20 | Q18: =+P18+O18 -> 24 | R18: =(N18/Q18) -> 117.33333 | S18: =(('Costo por negocio'!$B$2-DATA!R18)*DATA!O18)+('Costo por negocio'!$C$2-DATA!R18)*DATA!P18 -> 6076 | T18: 46045 | U18: SI | V18: SI | W18: SI | Y18: BAA 7043 | AA18: 94705 | AC18: 111 | AD18: 80374 | AE18: 46042.375 | AF18: 80408 | AG18: 46045.388 | AH18: =+AF18-AD18 -> 34 | AI18: 3 | AJ18: =+AI18*5 -> 15 | AK18: =+Q18-AJ18 -> 9 | AM18: =+AH18/Q18 -> 1.4166667 | AN18: =+Q18/AI18 -> 8 | AQ18: =+N18/78.54 -> 35.854342 | AR18: =+AH18/11 -> 3.0909091 | AS18: =+AR18-AQ18 -> -32.763433 | AT18: =+AH18/AQ18 -> 0.94828125
A19: 18 | B19: Lucia Santamaría | C19: 3065 | D19: 12 | E19: 15/01 al 31/01/2026 | F19: 46037 | G19: 46053 | J19: Maldonado | K19: Propio | M19: =+N19-H19 -> 600.5 | N19: 600.5 | O19: 9 | Q19: =+P19+O19 -> 9 | R19: =(N19/Q19) -> 66.722222 | S19: =(('Costo por negocio'!$B$2-DATA!R19)*DATA!O19)+('Costo por negocio'!$C$2-DATA!R19)*DATA!P19 -> 1766.5 | T19: 46037 | U19: SI | V19: SI | W19: SI | Y19: SBI 6680 | AH19: =+AF19-AD19 -> 0 | AJ19: =+AI19*5 -> 0 | AK19: =+Q19-AJ19 -> 9
A20: 19 | B20: Claudia Parrilla | C20: 2005 | D20: 3 | E20: 27/01 al 29/01/2026 | F20: 46049 | G20: 46051 | H20: =18*263 -> 4734 | I20: 15 | J20: Montevideo | K20: Alquiler | M20: =+N20-H20 -> -1683.41 | N20: 3050.59 | O20: =20+6 -> 26 | Q20: =+P20+O20 -> 26 | R20: =(N20/Q20) -> 117.33038 | S20: =(('Costo por negocio'!$B$2-DATA!R20)*DATA!O20)+('Costo por negocio'!$C$2-DATA!R20)*DATA!P20 -> 3787.41 | T20: 46052 | U20: SI | V20: SI | W20: SI | Y20: BEB 4233 | AA20: 94749 | AC20: 111 | AD20: 109722 | AE20: 46049.375 | AF20: 110060 | AG20: 46052.375 | AH20: =+AF20-AD20 -> 338 | AI20: 3 | AJ20: =+AI20*5 -> 15 | AK20: =+Q20-AJ20 -> 11 | AM20: =+AH20/Q20 -> 13 | AN20: =+Q20/AI20 -> 8.6666667 | AQ20: =+N20/78.54 -> 38.841227 | AR20: =+AH20/11 -> 30.727273 | AS20: =+AR20-AQ20 -> -8.1139547 | AT20: =+AH20/AQ20 -> 8.7020937
A21: 20 | B21: Lorena Cabrera | C21: 1618 | D21: 3 | E21: 27/01 al 29/01/2026 | F21: 46049 | G21: 46051 | H21: 4500 | I21: 15 | J21: Canelones, Maldonado | K21: Alquiler | M21: =+N21-H21 -> 256.1 | N21: =2000+2000+756.1 -> 4756.1 | O21: 11 | Q21: =+P21+O21 -> 11 | R21: =(N21/Q21) -> 432.37273 | S21: =(('Costo por negocio'!$B$2-DATA!R21)*DATA!O21)+('Costo por negocio'!$C$2-DATA!R21)*DATA!P21 -> -1863.1 | T21: 46056 | U21: SI | V21: SI | W21: SI | Y21: BEB 8412 | AA21: 93095 | AC21: 111 | AD21: 107721 | AE21: 46048.708 | AF21: 108502 | AG21: 46052.375 | AH21: =+AF21-AD21 -> 781 | AI21: 3 | AJ21: =+AI21*5 -> 15 | AK21: =+Q21-AJ21 -> -4
A22: 21 | B22: Ignacio Ceroni | C22: 3007 | D22: 4 | E22: 19/01 al 22/01/2026 | F22: 46041 | G22: 46044 | I22: 20 | J22: Montevideo | K22: Alquiler | M22: =+N22-H22 -> 3300.6 | N22: 3300.6 | O22: =18+11 -> 29 | Q22: =+P22+O22 -> 29 | R22: =(N22/Q22) -> 113.81379 | S22: =(('Costo por negocio'!$B$2-DATA!R22)*DATA!O22)+('Costo por negocio'!$C$2-DATA!R22)*DATA!P22 -> 4326.4 | T22: 46045 | U22: SI | V22: SI | W22: SI | Y22: BED 6748 | AA22: 94703 | AC22: 146 | AD22: 97593 | AE22: 46041.393 | AF22: 98027 | AG22: 46045.381 | AH22: =+AF22-AD22 -> 434 | AI22: 4 | AJ22: =+AI22*5 -> 20 | AK22: =+Q22-AJ22 -> 9 | AM22: =+AH22/Q22 -> 14.965517 | AN22: =+Q22/AI22 -> 7.25 | AQ22: =+N22/78.54 -> 42.024446 | AR22: =+AH22/11 -> 39.454545 | AS22: =+AR22-AQ22 -> -2.5699007 | AT22: =+AH22/AQ22 -> 10.327322
A23: 22 | B23: Ignacio Ceroni | C23: 3007 | D23: 12 | E23: 15/01 al 31/01/2026 | F23: 46037 | G23: 46053 | J23: Montevideo | K23: Propio | M23: =+N23-H23 -> 4568.1 | N23: =1800+2768.1 -> 4568.1 | O23: 9 | P23: 6 | Q23: =+P23+O23 -> 15 | R23: =(N23/Q23) -> 304.54 | S23: =(('Costo por negocio'!$B$2-DATA!R23)*DATA!O23)+('Costo por negocio'!$C$2-DATA!R23)*DATA!P23 -> 150.9 | T23: 46045 | U23: SI | V23: SI | W23: SI | Y23: SCG 4199 | AH23: =+AF23-AD23 -> 0 | AJ23: =+AI23*5 -> 0 | AK23: =+Q23-AJ23 -> 15
A24: 23 | B24: Lorena Cabrera | C24: 1618 | D24: 3 | E24: 20/01 al 22/01/2026 | F24: 46042 | G24: 46044 | I24: 15 | J24: Canelones, Maldonado | K24: Alquiler | M24: =+N24-H24 -> 3125.4 | N24: =2770.9+354.5 -> 3125.4 | O24: 10 | Q24: =+P24+O24 -> 10 | R24: =(N24/Q24) -> 312.54 | S24: =(('Costo por negocio'!$B$2-DATA!R24)*DATA!O24)+('Costo por negocio'!$C$2-DATA!R24)*DATA!P24 -> -495.4 | T24: 46049 | U24: SI | V24: SI | W24: SI | Y24: AAL 4305 | AA24: 93069 | AC24: 110 | AD24: 106904 | AE24: 46042.375 | AF24: 107433 | AG24: 46045.375 | AH24: =+AF24-AD24 -> 529 | AI24: 2 | AJ24: =+AI24*5 -> 10 | AK24: =+Q24-AJ24 -> 0 | AM24: =+AH24/Q24 -> 52.9 | AN24: =+Q24/AI24 -> 5 | AQ24: =+N24/78.54 -> 39.793736 | AR24: =+AH24/11 -> 48.090909 | AS24: =+AR24-AQ24 -> 8.2971734 | AT24: =+AH24/AQ24 -> 13.29355
A25: 24 | B25: Agustin Buñevaz | C25: 3152 | D25: 2 | E25: 22/01 al 23/01/2026 | F25: 46044 | G25: 46045 | I25: 10 | J25: Montevideo, Canelones | K25: Alquiler | M25: =+N25-H25 -> 2630 | N25: 2630 | O25: 10 | Q25: =+P25+O25 -> 10 | R25: =(N25/Q25) -> 263 | S25: =(('Costo por negocio'!$B$2-DATA!R25)*DATA!O25)+('Costo por negocio'!$C$2-DATA!R25)*DATA!P25 -> 0 | T25: 46049 | U25: SI | V25: SI | W25: SI | Y25: AAL 4328 | AA25: 93071 | AC25: 74 | AD25: 66471 | AE25: 46043.749 | AF25: 66806 | AG25: 46045.744 | AH25: =+AF25-AD25 -> 335 | AI25: 2 | AJ25: =+AI25*5 -> 10 | AK25: =+Q25-AJ25 -> 0 | AM25: =+AH25/Q25 -> 33.5 | AN25: =+Q25/AI25 -> 5 | AQ25: =+N25/78.54 -> 33.486122 | AR25: =+AH25/11 -> 30.454545 | AS25: =+AR25-AQ25 -> -3.0315763 | AT25: =+AH25/AQ25 -> 10.004144
A26: 25 | B26: Ricardo Cardona | C26: 1512 | D26: 3 | E26: 03/02 al 05/02/2026 | F26: 46056 | G26: 46058 | H26: 7000 | I26: 15 | J26: Montevideo, Río Negro | K26: Alquiler | M26: =+N26-H26 -> -592.2 | N26: =2065+2410+1932.8 -> 6407.8 | P26: 7 | Q26: =+P26+O26 -> 7 | R26: =(N26/Q26) -> 915.4 | S26: =(('Costo por negocio'!$B$2-DATA!R26)*DATA!O26)+('Costo por negocio'!$C$2-DATA!R26)*DATA!P26 -> -3663.8 | T26: 46049 | U26: SI | V26: SI | W26: SI | Y26: BEC 5528 | AA26: 94791 | AC26: 111 | AD26: 83208 | AE26: 46055.667 | AF26: 84167 | AG26: 46059.388 | AH26: =+AF26-AD26 -> 959 | AI26: 3 | AJ26: =+AI26*5 -> 15 | AK26: =+Q26-AJ26 -> -8 | AM26: =+AH26/Q26 -> 137 | AN26: =+Q26/AI26 -> 2.3333333 | AQ26: =+N26/78.54 -> 81.586453 | AR26: =+AH26/11 -> 87.181818 | AS26: =+AR26-AQ26 -> 5.5953654 | AT26: =+AH26/AQ26 -> 11.754402
A27: 26 | B27: Lorena Cabrera | C27: 1618 | D27: 3 | E27: 03/02 al 05/02/2026 | F27: 46056 | G27: 46058 | H27: 4500 | I27: 15 | J27: Canelones, Maldonado | K27: Alquiler | M27: =+N27-H27 -> -283.7 | N27: =2654.1+1562.2 -> 4216.3 | O27: 8 | Q27: =+P27+O27 -> 8 | R27: =(N27/Q27) -> 527.0375 | S27: =(('Costo por negocio'!$B$2-DATA!R27)*DATA!O27)+('Costo por negocio'!$C$2-DATA!R27)*DATA!P27 -> -2112.3 | T27: 46063 | U27: SI | V27: SI | W27: SI | Y27: BEC 5947 | AA27: 93099 | AC27: 111 | AD27: 71872 | AE27: 46055.708 | AF27: 72794 | AG27: 46059.403 | AH27: =+AF27-AD27 -> 922 | AI27: 3 | AJ27: =+AI27*5 -> 15 | AK27: =+Q27-AJ27 -> -7 | AM27: =+AH27/Q27 -> 115.25 | AN27: =+Q27/AI27 -> 2.6666667 | AQ27: =+N27/78.54 -> 53.683473 | AR27: =+AH27/11 -> 83.818182 | AS27: =+AR27-AQ27 -> 30.134708 | AT27: =+AH27/AQ27 -> 17.174746
A28: 27 | B28: Luis Amicone | C28: 3075 | D28: 3 | E28: 03/02 al 05/02/2026 | F28: 46056 | G28: 46058 | H28: 8000 | I28: 15 | J28: Montevideo, Salto | K28: Alquiler | M28: =+N28-H28 -> 1794.5 | N28: =1550+3848.1+2896.4+1500 -> 9794.5 | P28: =20+2 -> 22 | Q28: =+P28+O28 -> 22 | R28: =(N28/Q28) -> 445.20455 | S28: =(('Costo por negocio'!$B$2-DATA!R28)*DATA!O28)+('Costo por negocio'!$C$2-DATA!R28)*DATA!P28 -> -1170.5 | T28: 46059 | U28: SI | V28: SI | W28: SI | Y28: BED 2527 | AA28: 94790 | AC28: 111 | AD28: 101160 | AE28: 46055.663 | AF28: 102532 | AG28: 46059.379 | AH28: =+AF28-AD28 -> 1372 | AI28: 3 | AJ28: =+AI28*5 -> 15 | AK28: =+Q28-AJ28 -> 7 | AM28: =+AH28/Q28 -> 62.363636 | AN28: =+Q28/AI28 -> 7.3333333 | AQ28: =+N28/78.54 -> 124.70716 | AR28: =+AH28/11 -> 124.72727 | AS28: =+AR28-AQ28 -> 0.020117138 | AT28: =+AH28/AQ28 -> 11.001774
A29: 28 | B29: Natalia Greco | C29: 3154 | D29: 3 | E29: 03/02 al 05/02/2026 | F29: 46056 | G29: 46058 | H29: 5000 | I29: 15 | J29: Montevideo, San José | K29: Alquiler | M29: =+N29-H29 -> -1149 | N29: =1550+2301 -> 3851 | O29: =9+6 -> 15 | P29: 1 | Q29: =+P29+O29 -> 16 | R29: =(N29/Q29) -> 240.6875 | S29: =(('Costo por negocio'!$B$2-DATA!R29)*DATA!O29)+('Costo por negocio'!$C$2-DATA!R29)*DATA!P29 -> 486 | T29: 46059 | U29: SI | V29: SI | W29: SI | Y29: BED 7113 | AA29: 94781 | AC29: 111 | AD29: 108264 | AE29: 46055.708 | AF29: 108840 | AG29: 46058.673 | AH29: =+AF29-AD29 -> 576 | AI29: 3 | AJ29: =+AI29*5 -> 15 | AK29: =+Q29-AJ29 -> 1 | AM29: =+AH29/Q29 -> 36 | AN29: =+Q29/AI29 -> 5.3333333 | AQ29: =+N29/78.54 -> 49.03234 | AR29: =+AH29/11 -> 52.363636 | AS29: =+AR29-AQ29 -> 3.3312962 | AT29: =+AH29/AQ29 -> 11.747349
A30: 29 | B30: Luis Amicone | C30: 3075 | D30: 12 | E30: 15/01 al 31/01/2026 | F30: 46037 | G30: 46053 | J30: Montevideo | K30: Propio | M30: =+N30-H30 -> 7500 | N30: =2000+1000+2000+2000+500 -> 7500 | O30: =16+11 -> 27 | Q30: =+P30+O30 -> 27 | R30: =(N30/Q30) -> 277.77778 | S30: =(('Costo por negocio'!$B$2-DATA!R30)*DATA!O30)+('Costo por negocio'!$C$2-DATA!R30)*DATA!P30 -> -399 | T30: 46052 | U30: SI | V30: SI | W30: SI | Y30: SDA 5511
A31: 30 | B31: Rolando Ball | C31: 1332 | D31: 12 | E31: 15/01 al 31/01/2026 | F31: 46037 | G31: 46053 | J31: Rocha | K31: Propio | M31: =+N31-H31 -> 6300 | N31: =2000+2300+2000 -> 6300 | O31: =16+2 -> 18 | P31: 4 | Q31: =+P31+O31 -> 22 | R31: =(N31/Q31) -> 286.36364 | S31: =(('Costo por negocio'!$B$2-DATA!R31)*DATA!O31)+('Costo por negocio'!$C$2-DATA!R31)*DATA!P31 -> 2 | T31: 46056 | U31: SI | V31: SI | W31: SI | Y31: CBD 1303
A32: 31 | B32: Agustin Buñevaz | C32: 3152 | D32: 12 | E32: 15/01 al 31/01/2026 | F32: 46037 | G32: 46053 | J32: Montevideo, Canelones | K32: Propio | M32: =+N32-H32 -> 6312 | N32: =1052+1315+789+466+789+1052+849 -> 6312 | O32: =20+4 -> 24 | Q32: =+P32+O32 -> 24 | R32: =(N32/Q32) -> 263 | S32: =(('Costo por negocio'!$B$2-DATA!R32)*DATA!O32)+('Costo por negocio'!$C$2-DATA!R32)*DATA!P32 -> 0 | T32: 46056 | U32: SI | V32: SI | W32: SI | Y32: SBK 2846
A33: 32 | B33: Sylvia Antunez | C33: 3064 | D33: 12 | E33: 15/01 al 31/01/2026 | F33: 46037 | G33: 46053 | J33: Montevideo, Canelones | K33: Propio | M33: =+N33-H33 -> 2114 | N33: 2114 | O33: =11+5+6+1 -> 23 | Q33: =+P33+O33 -> 23 | R33: =(N33/Q33) -> 91.913043 | S33: =(('Costo por negocio'!$B$2-DATA!R33)*DATA!O33)+('Costo por negocio'!$C$2-DATA!R33)*DATA!P33 -> 3935 | T33: 46056 | U33: SI | V33: SI | W33: SI | Y33: SDD 4937
A34: 33 | B34: Fernando López | C34: 3117 | D34: 12 | E34: 15/01 al 31/01/2026 | F34: 46037 | G34: 46053 | J34: Montevideo | K34: Propio | M34: =+N34-H34 -> 5500.6 | N34: =3000+2500.6 -> 5500.6 | O34: =11+10 -> 21 | Q34: =+P34+O34 -> 21 | R34: =(N34/Q34) -> 261.93333 | S34: =(('Costo por negocio'!$B$2-DATA!R34)*DATA!O34)+('Costo por negocio'!$C$2-DATA!R34)*DATA!P34 -> 22.4 | T34: 46056 | U34: SI | V34: SI | W34: SI | Y34: SCL 8868
A35: 34 | B35: Claudia Parrilla | C35: 2005 | D35: 3 | E35: 10/02 al 12/02/2026 | F35: 46063 | G35: 46065 | H35: =30*392 -> 11760 | I35: 15 | J35: Montevideo, Artigas | K35: Alquiler | M35: =+N35-H35 -> -4188.2 | N35: =2527+2349.5+1428.6+1266.7 -> 7571.8 | P35: =20+2 -> 22 | Q35: =+P35+O35 -> 22 | R35: =(N35/Q35) -> 344.17273 | S35: =(('Costo por negocio'!$B$2-DATA!R35)*DATA!O35)+('Costo por negocio'!$C$2-DATA!R35)*DATA!P35 -> 1052.2 | T35: 46066 | U35: SI | V35: SI | W35: SI | Y35: BEB 9257 | AA35: 95450 | AC35: 111 | AD35: 81267 | AE35: 46062.708 | AF35: 82641 | AG35: 46066.388 | AH35: =+AF35-AD35 -> 1374 | AI35: 3 | AJ35: =+AI35*5 -> 15 | AK35: =+Q35-AJ35 -> 7 | AM35: =+AH35/Q35 -> 62.454545 | AN35: =+Q35/AI35 -> 7.3333333 | AQ35: =+N35/78.54 -> 96.406926 | AR35: =+AH35/11 -> 124.90909 | AS35: =+AR35-AQ35 -> 28.502165 | AT35: =+AH35/AQ35 -> 14.252088
A36: 35 | B36: Ricardo Cardona | C36: 1512 | D36: 3 | E36: 10/02 al 12/02/2026 | F36: 46063 | G36: 46065 | H36: 6000 | I36: 15 | J36: Montevideo, Flores, Durazno | K36: Alquiler | M36: =+N36-H36 -> -1479.8 | N36: =2200+1820.2+500 -> 4520.2 | P36: 10 | Q36: =+P36+O36 -> 10 | R36: =(N36/Q36) -> 452.02 | S36: =(('Costo por negocio'!$B$2-DATA!R36)*DATA!O36)+('Costo por negocio'!$C$2-DATA!R36)*DATA!P36 -> -600.2 | T36: 46066 | U36: SI | V36: SI | W36: SI | Y36: BEC 5478 | AA36: 95446 | AC36: 111 | AD36: 78049 | AE36: 46062.66 | AF36: 78681 | AG36: 46066.378 | AH36: =+AF36-AD36 -> 632 | AI36: 3 | AJ36: =+AI36*5 -> 15 | AK36: =+Q36-AJ36 -> -5 | AM36: =+AH36/Q36 -> 63.2 | AN36: =+Q36/AI36 -> 3.3333333 | AQ36: =+N36/78.54 -> 57.552839 | AR36: =+AH36/11 -> 57.454545 | AS36: =+AR36-AQ36 -> -0.098293863 | AT36: =+AH36/AQ36 -> 10.981213
A37: 36 | B37: Fernando López | C37: 3117 | D37: 3 | E37: 10/02 al 12/02/2026 | F37: 46063 | G37: 46065 | H37: 3000 | I37: 15 | J37: Montevideo | K37: Alquiler | M37: =+N37-H37 -> 571.2 | N37: =2200.5+1370.7 -> 3571.2 | O37: 6 | P37: 11 | Q37: =+P37+O37 -> 17 | R37: =(N37/Q37) -> 210.07059 | S37: =(('Costo por negocio'!$B$2-DATA!R37)*DATA!O37)+('Costo por negocio'!$C$2-DATA!R37)*DATA!P37 -> 2318.8 | T37: 46066 | U37: SI | V37: SI | W37: SI | Y37: BEC 2029 | AA37: 95447 | AC37: 111 | AD37: 131518 | AE37: 46062.708 | AF37: 132048 | AG37: 46066.382 | AH37: =+AF37-AD37 -> 530 | AI37: 3 | AJ37: =+AI37*5 -> 15 | AK37: =+Q37-AJ37 -> 2 | AM37: =+AH37/Q37 -> 31.176471 | AN37: =+Q37/AI37 -> 5.6666667 | AQ37: =+N37/78.54 -> 45.469824 | AR37: =+AH37/11 -> 48.181818 | AS37: =+AR37-AQ37 -> 2.7119939 | AT37: =+AH37/AQ37 -> 11.656082
A38: 37 | B38: Ignacio Ceroni | C38: 3007 | D38: 4 | E38: 09/02 al 12/02/2026 | F38: 46062 | G38: 46065 | H38: 3000 | I38: 20 | J38: Montevideo | K38: Alquiler | M38: =+N38-H38 -> 467.1 | N38: =3066.5+400.6 -> 3467.1 | O38: =20+10 -> 30 | Q38: =+P38+O38 -> 30 | R38: =(N38/Q38) -> 115.57 | S38: =(('Costo por negocio'!$B$2-DATA!R38)*DATA!O38)+('Costo por negocio'!$C$2-DATA!R38)*DATA!P38 -> 4422.9 | T38: 46066 | U38: SI | V38: SI | W38: SI | Y38: BEC 5634 | AA38: 95449 | AC38: 148 | AD38: 82664 | AE38: 46062.375 | AF38: 83123 | AG38: 46066.385 | AH38: =+AF38-AD38 -> 459 | AI38: 4 | AJ38: =+AI38*5 -> 20 | AK38: =+Q38-AJ38 -> 10 | AM38: =+AH38/Q38 -> 15.3 | AN38: =+Q38/AI38 -> 7.5 | AQ38: =+N38/78.54 -> 44.144385 | AR38: =+AH38/11 -> 41.727273 | AS38: =+AR38-AQ38 -> -2.4171123 | AT38: =+AH38/AQ38 -> 10.397698
A39: 38 | B39: Luis Amicone | C39: 3075 | D39: 3 | E39: 10/02 al 12/02/2026 | F39: 46063 | G39: 46065 | H39: 8000 | I39: 15 | J39: Montevideo, Tacuarembo | K39: Alquiler | M39: =+N39-H39 -> -780.6 | N39: =2901+2800.4+1518 -> 7219.4 | P39: =20+1 -> 21 | Q39: =+P39+O39 -> 21 | R39: =(N39/Q39) -> 343.78095 | S39: =(('Costo por negocio'!$B$2-DATA!R39)*DATA!O39)+('Costo por negocio'!$C$2-DATA!R39)*DATA!P39 -> 1012.6 | T39: 46066 | U39: SI | V39: SI | W39: SI | Y39: BED 2529 | AA39: 95435 / NC 13549 | AC39: =111-37 -> 74 | AD39: 79309 | AE39: 46062.667 | AF39: 80279 | AG39: 46065.382 | AH39: =+AF39-AD39 -> 970 | AI39: 2 | AJ39: =+AI39*5 -> 10 | AK39: =+Q39-AJ39 -> 11 | AM39: =+AH39/Q39 -> 46.190476 | AN39: =+Q39/AI39 -> 10.5 | AQ39: =+N39/78.54 -> 91.920041 | AR39: =+AH39/11 -> 88.181818 | AS39: =+AR39-AQ39 -> -3.7382226 | AT39: =+AH39/AQ39 -> 10.55265
A40: 39 | B40: Lorena Cabrera | C40: 1618 | D40: 3 | E40: 10/02 al 12/02/2026 | F40: 46063 | G40: 46065 | H40: 4500 | I40: 15 | J40: Canelones, Maldonado, Lavalleja | K40: Alquiler | M40: =+N40-H40 -> 1000.8 | N40: =2500.3+3000.5 -> 5500.8 | O40: 9 | P40: 3 | Q40: =+P40+O40 -> 12 | R40: =(N40/Q40) -> 458.4 | S40: =(('Costo por negocio'!$B$2-DATA!R40)*DATA!O40)+('Costo por negocio'!$C$2-DATA!R40)*DATA!P40 -> -1957.8 | T40: 46073 | U40: SI | V40: SI | W40: SI | Y40: BEB 9280 | AA40: 93119 | AC40: 111 | AD40: 99981 | AE40: 46062.708 | AF40: 101018 | AG40: 46066.403 | AH40: =+AF40-AD40 -> 1037 | AI40: 3 | AJ40: =+AI40*5 -> 15 | AK40: =+Q40-AJ40 -> -3 | AM40: =+AH40/Q40 -> 86.416667 | AN40: =+Q40/AI40 -> 4 | AQ40: =+N40/78.54 -> 70.038197 | AR40: =+AH40/11 -> 94.272727 | AS40: =+AR40-AQ40 -> 24.23453 | AT40: =+AH40/AQ40 -> 14.806206
...

Sheet Costo por negocio
A1: Mes | B1: Menos de 100KM | C1: Más de 100KM
A2: 46023 | B2: 263 | C2: 392
A3: 46082 | B3: 260 | C3: 387
A4: 46113 | B4: 278 | C4: 414
A5: 46143 | B5: 297 | C5: 443
A12: Costo máximo por Negocio Actual: | B12: =B5 -> 297 | C12: =C5 -> 443

Sheet Costo Combustible
A1: AJUSTES DE PRECIOS DE COMBUSTIBLES DESDE 01/05/2026
B2: Precio Nafta
A3: Concepto | B3: 46113 | C3: 46143 | D3: Diferencia $ | E3: Variación %
D4: Abril 2026 a Mayo 2026 | E4: Abril 2026 a Mayo 2026
A5: Nafta super | B5: 82.27 | C5: 88.03 | D5: =+C5-B5 -> 5.76 | E5: =+D5/B5 -> 0.070013371
A6: Menos 100 km. | B6: 277.96888 | C6: =B6+(B6*E5) -> 297.43042 | D6: =+C6-B6 -> 19.461538 | E6: =+D6/B6 -> 0.070013371
A7: Más 100 km. | B7: 414.2066 | C7: =B7+(B7*E6) -> 443.2066 | D7: =+C7-B7 -> 29 | E7: =+D7/B7 -> 0.070013371
